<?xml version="1.0" encoding="UTF-8"?>
<testng-results skipped="0" failed="2" total="3" passed="1">
  <reporter-output>
  </reporter-output>
  <suite name="Suite1" duration-ms="73" started-at="2014-07-17T10:46:56Z" finished-at="2014-07-17T10:46:56Z">
    <groups>
    </groups>
    <test name="exampletest1" duration-ms="27" started-at="2014-07-17T10:46:56Z" finished-at="2014-07-17T10:46:56Z">
      <class name="com.assignment52.TestNGSuiteTest.Test1">
        <test-method status="PASS" signature="testPrint1Message()[pri:0, instance:com.assignment52.TestNGSuiteTest.Test1@74f9fb]" name="testPrint1Message" duration-ms="14" started-at="2014-07-17T16:16:56Z" finished-at="2014-07-17T16:16:56Z">
          <reporter-output>
          </reporter-output>
        </test-method> <!-- testPrint1Message -->
      </class> <!-- com.assignment52.TestNGSuiteTest.Test1 -->
    </test> <!-- exampletest1 -->
    <test name="exampletest2" duration-ms="4" started-at="2014-07-17T10:46:56Z" finished-at="2014-07-17T10:46:56Z">
      <class name="com.assignment52.TestNGSuiteTest.Test2">
        <test-method status="FAIL" signature="testPrint2Message()[pri:0, instance:com.assignment52.TestNGSuiteTest.Test2@1eb84f]" name="testPrint2Message" duration-ms="1" started-at="2014-07-17T16:16:56Z" finished-at="2014-07-17T16:16:56Z">
          <exception class="java.lang.AssertionError">
            <message>
              <![CDATA[expected [Hirevathi] but found [Hi!revathi]]]>
            </message>
            <full-stacktrace>
              <![CDATA[java.lang.AssertionError: expected [Hirevathi] but found [Hi!revathi]
	at org.testng.Assert.fail(Assert.java:94)
	at org.testng.Assert.failNotEquals(Assert.java:494)
	at org.testng.Assert.assertEquals(Assert.java:123)
	at org.testng.Assert.assertEquals(Assert.java:176)
	at org.testng.Assert.assertEquals(Assert.java:186)
	at com.assignment52.TestNGSuiteTest.Test2.testPrint2Message(Test2.java:16)
	at sun.reflect.NativeMethodAccessorImpl.invoke0(Native Method)
	at sun.reflect.NativeMethodAccessorImpl.invoke(Unknown Source)
	at sun.reflect.DelegatingMethodAccessorImpl.invoke(Unknown Source)
	at java.lang.reflect.Method.invoke(Unknown Source)
	at org.testng.internal.MethodInvocationHelper.invokeMethod(MethodInvocationHelper.java:84)
	at org.testng.internal.Invoker.invokeMethod(Invoker.java:714)
	at org.testng.internal.Invoker.invokeTestMethod(Invoker.java:901)
	at org.testng.internal.Invoker.invokeTestMethods(Invoker.java:1231)
	at org.testng.internal.TestMethodWorker.invokeTestMethods(TestMethodWorker.java:127)
	at org.testng.internal.TestMethodWorker.run(TestMethodWorker.java:111)
	at org.testng.TestRunner.privateRun(TestRunner.java:767)
	at org.testng.TestRunner.run(TestRunner.java:617)
	at org.testng.SuiteRunner.runTest(SuiteRunner.java:334)
	at org.testng.SuiteRunner.runSequentially(SuiteRunner.java:329)
	at org.testng.SuiteRunner.privateRun(SuiteRunner.java:291)
	at org.testng.SuiteRunner.run(SuiteRunner.java:240)
	at org.testng.SuiteRunnerWorker.runSuite(SuiteRunnerWorker.java:52)
	at org.testng.SuiteRunnerWorker.run(SuiteRunnerWorker.java:86)
	at org.testng.TestNG.runSuitesSequentially(TestNG.java:1224)
	at org.testng.TestNG.runSuitesLocally(TestNG.java:1149)
	at org.testng.TestNG.run(TestNG.java:1057)
	at org.testng.remote.RemoteTestNG.run(RemoteTestNG.java:111)
	at org.testng.remote.RemoteTestNG.initAndRun(RemoteTestNG.java:204)
	at org.testng.remote.RemoteTestNG.main(RemoteTestNG.java:175)
]]>
            </full-stacktrace>
          </exception> <!-- java.lang.AssertionError -->
          <reporter-output>
          </reporter-output>
        </test-method> <!-- testPrint2Message -->
      </class> <!-- com.assignment52.TestNGSuiteTest.Test2 -->
    </test> <!-- exampletest2 -->
    <test name="exampletest3" duration-ms="3" started-at="2014-07-17T10:46:56Z" finished-at="2014-07-17T10:46:56Z">
      <class name="com.assignment52.TestNGSuiteTest.Test3">
        <test-method status="FAIL" signature="testFinalMessage()[pri:0, instance:com.assignment52.TestNGSuiteTest.Test3@13ef605]" name="testFinalMessage" duration-ms="1" started-at="2014-07-17T16:16:56Z" finished-at="2014-07-17T16:16:56Z">
          <exception class="java.lang.AssertionError">
            <message>
              <![CDATA[expected [Hi testng is working finerevathi] but found [Hi testng is working fine!revathi]]]>
            </message>
            <full-stacktrace>
              <![CDATA[java.lang.AssertionError: expected [Hi testng is working finerevathi] but found [Hi testng is working fine!revathi]
	at org.testng.Assert.fail(Assert.java:94)
	at org.testng.Assert.failNotEquals(Assert.java:494)
	at org.testng.Assert.assertEquals(Assert.java:123)
	at org.testng.Assert.assertEquals(Assert.java:176)
	at org.testng.Assert.assertEquals(Assert.java:186)
	at com.assignment52.TestNGSuiteTest.Test3.testFinalMessage(Test3.java:17)
	at sun.reflect.NativeMethodAccessorImpl.invoke0(Native Method)
	at sun.reflect.NativeMethodAccessorImpl.invoke(Unknown Source)
	at sun.reflect.DelegatingMethodAccessorImpl.invoke(Unknown Source)
	at java.lang.reflect.Method.invoke(Unknown Source)
	at org.testng.internal.MethodInvocationHelper.invokeMethod(MethodInvocationHelper.java:84)
	at org.testng.internal.Invoker.invokeMethod(Invoker.java:714)
	at org.testng.internal.Invoker.invokeTestMethod(Invoker.java:901)
	at org.testng.internal.Invoker.invokeTestMethods(Invoker.java:1231)
	at org.testng.internal.TestMethodWorker.invokeTestMethods(TestMethodWorker.java:127)
	at org.testng.internal.TestMethodWorker.run(TestMethodWorker.java:111)
	at org.testng.TestRunner.privateRun(TestRunner.java:767)
	at org.testng.TestRunner.run(TestRunner.java:617)
	at org.testng.SuiteRunner.runTest(SuiteRunner.java:334)
	at org.testng.SuiteRunner.runSequentially(SuiteRunner.java:329)
	at org.testng.SuiteRunner.privateRun(SuiteRunner.java:291)
	at org.testng.SuiteRunner.run(SuiteRunner.java:240)
	at org.testng.SuiteRunnerWorker.runSuite(SuiteRunnerWorker.java:52)
	at org.testng.SuiteRunnerWorker.run(SuiteRunnerWorker.java:86)
	at org.testng.TestNG.runSuitesSequentially(TestNG.java:1224)
	at org.testng.TestNG.runSuitesLocally(TestNG.java:1149)
	at org.testng.TestNG.run(TestNG.java:1057)
	at org.testng.remote.RemoteTestNG.run(RemoteTestNG.java:111)
	at org.testng.remote.RemoteTestNG.initAndRun(RemoteTestNG.java:204)
	at org.testng.remote.RemoteTestNG.main(RemoteTestNG.java:175)
]]>
            </full-stacktrace>
          </exception> <!-- java.lang.AssertionError -->
          <reporter-output>
          </reporter-output>
        </test-method> <!-- testFinalMessage -->
      </class> <!-- com.assignment52.TestNGSuiteTest.Test3 -->
    </test> <!-- exampletest3 -->
  </suite> <!-- Suite1 -->
</testng-results>
